Workbook

Sheet PETUNJUK PENGERJAAN
B6: PETUNJUK PENGERJAAN LAPORAN ADMIN TERBARU
A7: 1. | B7: LAPORAN LPKK
B9: Form laporan LPKK tidak diprotect/dikunci, supervisor dapat menambahkan kolom LPKK apabila nota pembelanjaan dalam satu hari melebihi kolom yang disediakan
B10: Pada format laporan LPKK terbaru, kolom Bahan Roti dan Bahan Perkedel dihilangkan.
B11: Nota - nota belanja Bahan Roti dialihkan masuk ke kolom Bahan Pelengkap dan untuk nota- nota Bahan Perkedel masuk kolom Bumbu/Groceries
A13: 2. | B13: LAPORAN VENDOR
B14: Pembelian ayam cash diisi secara manual dan pembelian ayam kredit wajib diisi dikolom khusus pembelian ayam kredit dan marinade
B15: Pengerjaan laporan secara online/komputer nota ayam kredit diisi pada kolom kanan atas laporan vendor yang secara otomatis mengisi pada kolom khusus ayam kredit pada vendor
B16: Kolom TO/TI pada vendor dikerjakan secara manual dan pencatatan diperhatikan, apabila Ada TO (Transfer Out) pencatatan nominal harus diberi tanda (-).
B17: Penambahan keterangan bahan baku pada kolom vendor dapat diisi lewat laporan weekly pada kolom bahan sesuai dengan pengelompokkan bahan bakunya, maka secara langsung akan ngelink ke kolom keterangan bahan baku di laporan vendor
B18: Hasil print out laporan vendor pengerjaan secara online/komputer menjadi 3 lembar, pengerjaan secara manual vendor menjadi 5 lembar
A20: 3. | B20: COST ANALYSIS
B21: Kolom penjualan pada laporan cost analysis diisi secara manual. Kolom penjualan bisa dibuat rumus oleh supervisor sesuai dengan kelas masing - masing dengan cara total unit penjualan ngelink dengan semua laporan penjualan offline/online (gofood, grabfood, shopee food) contoh penghitungan MENCARI PENJUALAN PRODUK P. BAWAH (KETIK = pada laporan cost analysis kolom penjualan P. BAWAH kemudian klik pada laporan LP, Total unit penjualan P. BAWAH pada setiap produk item satuan/paket yang ada produk P. BAWAH dengan menambahkan tanda + pada semua Laporan penjualan termasuk LP online) KEMUDIAN TEKAN ENTER.
A23: 4. | B23: LAPORAN KAS & PENJUALAN PER PERIODE
B24: Kolom Tax/Pajak (FULL PPN) wajib diisi store yang sudah mengenakan harga jual ke customer plus PPN/Pajak (full customer dikenakan pajak) Harga jual produk per item di laporan penjualan harga menu price harus sudah plus PPN
B25: Kolom Tax/Pajak (SEBAGIAN PPN), wajib diisi store yang sudah mengenakan harga jual ke customer plus PPN/Pajak (sebagian cutomer yang dikenakan pajak) Harga jual produk per item di laporan penjualan harga menu price tanpa plus PPN
B26: Store yang belum mengenakan pajak kepada customer kolom tax atau pajak tidak perlu diisi/dikosongkan
A28: 5. | B28: LAPORAN TO/TI
B29: Laporan TO/TI hasil jumlah akan ngelink dengan laporan ikhtisar food cost
B30: Pengerjaan TO/TI terdapat petunjuk pengerjaan di sheet TO/TI
A33: 6. | B33: LAPORAN LKK
B34: Store yang belum mengenakan PPN kepada customer mengunakan lkk dengan rumus Penjualan Kotor - Komisi - Koreksi - Diskon = Penjualan Bersih
B35: Store yang sudah mengenakan PPN kepada customer sebagian mengunakan lkk dengan rumus Penjualan Kotor - Komisi - Koreksi - Diskon = Penjualan Bersih
B36: Store yang sudah mengenakan FULL PPN kepada customer mengunakan lkk dengan rumus Penjualan Kotor - Komisi - Koreksi - Diskon - PAJAK/TAX = Penjualan Bersih
A38: 7. | B38: LAPORAN PENJUALAN
B39: Pengisian tanggal pada kolom unit penjualan per hari hanya diisi tanggalnya saja, tidak dengan Bulan dan Tahun agar saat diprint out hasil lebih maksimal
B40: Laporan penjualan untuk store yang sudah mengenakan FULL PPN harga wajib disesuaikan + PPN
B41: Laporan penjualan PPN 10 % untuk Harga (unit) diisi manual sesuai harga menu price sebelum tambah PPN
B42: Laporan admin terbaru terdapat 4 laporan penjualan (LP) yaitu LP Penjualan Reguler, LP Gofood, LP Grabfood dan LP Shopee food. Apabila store tidak ada penjualan via online atau hanya salah satu yang ada, maka LP yang lain/yang tidak dipakai TIDAK BOLEH DIHAPUS (CUKUP KOSONGKAN SAJA)
B43: Laporan penjualan hasil print out menjadi 3 lembar/disesuaikan dengan ukuran yang layak agar dapat dibaca dan dikoreksi
B44: Apabila dalam laporan LP kolom yang disediakan kurang karena penambahan produk baru, supervisor bisa konfirm ke Area Manger untuk segera diteruskan dan di follow up/atau di perbaiki oleh team TC
A46: 8. | B46: Apabila saat pengerjaan laporan menemukan kendala pada rumus seperti Reff!, solusi awal bisa dilakukan undo typing (ctrl + Z) untuk mengembalikan kesalahan saat pengerjaan atau bisa dengan menutup file pengerjaan laporan dan untuk tidak di simpan atau don't save pada laporan tersebut. Apabila laporan masih erorr supervisor bisa konfirm team TC agar dapat dibantu perbaiki laporan yang error atau tidak sesuai
A48: 9. | B48: Sheet food cost per item dibuat untuk acuan cara pengerjaan/mencari food cost pada setiap menu. Food cost item per paket supervisor bisa modifikasi dengan acuan hitungan yang sudah ada sesuai dengan komposisi paket dan kelas masing - masing
A50: 10. | B50: Apabila pada setiap format laporan mengharuskan adanya penambahan kolom, supervisor bisa menyampaikan kepada Area Manager untuk diteruskan ke team TC agar segera di follow up
A52: 11. | B52: Supervisor dapat memodifikasi laporan pada kolom - kolom yang tidak dikunci oleh team TC dengan catatan tidak untuk merubah rumus yang sudah ada yang akan mempengaruhi hasil penghitungan
A54: 12. | B54: Supervisor harus tetap memperhatikan hasil print out dari laporan - laporan yang sudah dikerjakan untuk melakukan pengecekan dari ukuran kertas, ukuran tulisan dan skala print out dan diperhatikan tulisan kiranya dapat dibaca dengan jelas atau tidaknya sebelum dikirim ke kantor dan dicek oleh team acoounting
A56: 13 | B56: TO/TI PERKEDEL MANUAL TIDAK TERUMUS PENGERJAAN SECARA MANUAL
A58: 14 | B58: PENCATATAN UNIT CABAI RAWIT PADA KOLOM VENDOR ADALAH GRAMASI CABAI YANG SUDAH DIPETIK (CABAI TANPA TANGKAI)

Sheet SOP ADMINISTRASI
B6: SOP PENGERJAAN ADMINISTRASI STORE
A8: 1 | B8: Pembelian paper polos seperti tutup cup minum polos/karakter, kertas KFC/kertas minyak (kertas warna coklat), kantong kertas ayam/burger, cup saos/cup pudding/cup 35ml, cover nasi polos tidak diperbolehkan beli dari luar warehouse RC dengan alasan apapun (NB : untuk plastik jumbo polos selama warehouse belum tersedia, masih ada toleransi untuk beli di luar)
A10: 2 | B10: Reimburse pulsa store (Rp 40.000) harus disertai screenshoot-an SMS masuk pulsa tersebut/nota asli dari counter dan harus tertera nomor yang diisi pulsa tersebut yaitu nomor store
A12: 3 | B12: Standarisasi nota adalah harus tertera tanggal, nama toko barang/item yang dibeli dengan jelas (jika hanya tertera kode barang, harap dituliskan dengan jelas barang tersebut) disertai stempel dan nomor HP toko, tanda tangan dan nama SPV
A14: 4 | B14: Transport pesanan/klaim free pesanan harus melampirkan nota pesanan dan struk postingan pesanan tersebut
A16: 5 | B16: Untuk vitamin, tidak diperbolehkan (yang termasuk ke dalam P3K adalah obat-obatan untuk kecelakaan yang terjadi saat di store, misalnya luka bakar/luka terkena pisau)
A18: 6 | B18: Gunting kuku, cukur kumis, semir sepatu, sisir (keperluan pribadi) dan lain-lain atau peralatan yang digunakan untuk penunjang kerapihan penampilan karyawan tidak diperbolehkan reimburst store (tunjangan penampilan sudah tertera pada gaji)
A20: 7 | B20: All administrasi staff (LKK, STOCK CONTROL, MCC, LO) dan all administrasi supervisor yang dikirim ke kantor wajib dikroscek dan diparaf supervisor
A22: 8 | B22: All laporan sebelum dikirim ke kantor/accounting, supervisor wajib kroscek form laporan-laporan dari kelengkapan form laporan, ukuran font dan kerapihan cetak/print laporan
A24: 9 | B24: BAHAN BAKU TELUR DAN CABAI RAWIT DI VENDOR TIDAK LAGI MASUK KEDALAM BAHAN NASGOR
A26: 10 | B26: PENCATATAN UNIT CABAI RAWIT PADA KOLOM VENDOR ADALAH GRAMASI CABAI YANG SUDAH DIPETIK (CABAI TANPA TANGKAI)

Sheet WEEKLY FC
A3: WEEKLY / MONTHLY INVENTORI
E5: Cabang : | F5: =LPKK!O4 -> RC SAMATA GOWA
E6: Periode : | F6: =LPKK!O5 -> 8-14 JANUARI 2025
A9: NO | B9: BAHAN | C9: UNIT | D9: QTY | E9: PRICE | F9: TOTAL (Rp)
A10: I | B10: BAHAN AYAM
A11: 1 | B11: DADA MENTOK | C11: PCS | D11: 112.3 | E11: 6154.7692 | F11: =D11*E11 -> 691180.58
A12: 2 | B12: DADA | C12: PCS | D12: 208 | E12: 7385.7231 | F12: =D12*E12 -> 1536230.4
A13: 3 | B13: PAHA ATAS | C13: PCS | D13: 208 | E13: 5949.6103 | F13: =D13*E13 -> 1237518.9
A14: 4 | B14: PAHA BAWAH | C14: PCS | D14: 240 | E14: 3898.0192 | F14: =D14*E14 -> 935524.62
A15: 5 | B15: SAYAP | C15: PCS | D15: 210 | E15: 4308.3385 | F15: =D15*E15 -> 904751.08 | K15: PRINT LEMBAR 1 | L15: =SUM(D11:D15) -> 978.3
A16: 6 | B16: CHICKEN PATTY | C16: PCS | D16: 11 | E16: 3729.3603 | F16: =D16*E16 -> 41022.963 | L16: =L15/414 -> 2.3630435
A17: 7 | B17: SAYAP TANPA KOLAR | C17: PCS | F17: =D17*E17 -> 0
A18: 8 | B18: PATTY BEEF | C18: PCS | F18: =D18*E18 -> 0
A19: 9 | B19: BEEF STEAK | C19: PCS | F19: =D19*E19 -> 0
A20: 10 | B20: DADA MENTOK TAKJIL | C20: PCS | E20: 4904.8889 | F20: =D20*E20 -> 0
A21: 11 | B21: DADA TAKJIL | C21: PCS | E21: 5722.3704 | F21: =D21*E21 -> 0
A22: 12 | B22: PAHA ATAS TAKJIL | C22: PCS | E22: 5313.6296 | F22: =D22*E22 -> 0
A23: 13 | B23: PAHA BAWAH TAKJIL | C23: PCS | E23: 3269.9259 | F23: =D23*E23 -> 0
A24: 14 | B24: SAYAP TAKJIL | C24: PCS | E24: 3678.6667 | F24: =D24*E24 -> 0
A25: 15 | B25: AYAM UTUH | C25: EKOR | D25: 30 | E25: 35000 | F25: =D25*E25 -> 1050000
A26: 16 | F26: =D26*E26 -> 0
A27: 17 | F27: =D27*E27 -> 0
A28: 18 | F28: =D28*E28 -> 0
A29: 19 | F29: =D29*E29 -> 0
A30: 20 | F30: =D30*E30 -> 0
E31: JUMLAH | F31: =SUM(F11:F30) -> 6396228.6
A32: II | B32: BAHAN PELENGKAP
A33: 1 | B33: VEGETABLE MIX | C33: KG | D33: 2.5 | E33: 30000 | F33: =D33*E33 -> 75000
A34: 2 | B34: BERAS | C34: KG | D34: 78 | E34: 14000 | F34: =D34*E34 -> 1092000
A35: 3 | B35: FRENCH FRIES | C35: KG | D35: 2.3 | E35: 26000 | F35: =D35*E35 -> 59800
A36: 4 | B36: ROTI BURGER | C36: PCS | D36: 69 | E36: 2907.0833 | F36: =D36*E36 -> 200588.75
A37: 5 | B37: SOSIS | C37: PCS | F37: =D37*E37 -> 0
A38: 6 | B38: PERKEDEL | C38: PCS | D38: 72 | E38: ='TO - TI'!D22 -> 1649.8049 | F38: =D38*E38 -> 118785.95
A39: 7 | B39: CRINKLE | C39: KG | D39: 0.7 | E39: 32000 | F39: =D39*E39 -> 22400
A40: 8 | B40: NUGGET COIN | C40: PCS | F40: =D40*E40 -> 0
A41: 9 | B41: NUGGET STICK | C41: PCS | F41: =D41*E41 -> 0
A42: 10 | B42: SOSIS MINI JUMBO | C42: PCS | F42: =D42*E42 -> 0
A43: 11 | B43: INDOMIE GORENG | C43: PACK | F43: =D43*E43 -> 0
A44: 12 | B44: KERUPUK UDANG | C44: PACK | F44: =D44*E44 -> 0
A45: 13 | B45: BUN BURGER BEEF | C45: PCS | F45: =D45*E45 -> 0
...

Sheet PEMBELIAN KREDIT
A5: LAPORAN PEMBELIAN BAHAN ( KREDIT )
H7: CABANG | I7: : | J7: =LPKK!O4 -> RC SAMATA GOWA
H8: PERIODE | I8: : | J8: =LPKK!O5 -> 8-14 JANUARI 2025
A10: TANGGAL | B10: NAMA SUPLIER | C10: NAMA BAHAN | D10: NOMOR | E10: JUMLAH | F10: HARGA | G10: TOTAL | H10: LAMA | K10: TANGGAL
D11: FAKTUR | E11: ( UNIT ) | F11: ( UNIT ) | H11: KREDIT | J11: JATUH TEMPO | K11: DIBAYAR
B14: PT CIOMAS ADISATWA | C14: MENTOK | E14: 130 | F14: =G14/E14 -> 5981.5865 | G14: =6220850/1200*150 -> 777606.25 | L14: =E14/46 -> 2.826087
C15: DADA | E15: 260 | F15: =G15/E15 -> 7177.9038 | G15: =6220850/1200*180*2 -> 1866255 | M15: =E20/60 -> 0.5
C16: PAHA ATAS | E16: 260 | F16: =G16/E16 -> 5782.2003 | G16: =6220850/1200*145*2 -> 1503372.1
C17: PAHA BAWAH | E17: 260 | F17: =G17/E17 -> 3788.3381 | G17: =6220850/1200*95*2 -> 984967.92
C18: SAYAP | E18: 260 | F18: =G18/E18 -> 4187.1106 | G18: =6220850/1200*105*2 -> 1088648.8
A20: 46035 | C20: AYAM UTUH | E20: 30 | F20: =G20/E20 -> 34000 | G20: 1020000
G21: =SUM(G14:G20) -> 7240850 | L21: =G14*11% -> 85536.688
A22: 46034 | B22: PT SINAR GOWA SUKSES | C22: PRIMA BOTOL | E22: 120 | F22: =G22/E22 -> 1666.6667 | G22: 200000
C23: STEE KOTAK | E23: 240 | F23: =G23/E23 -> 1583.9708 | G23: 380153
C24: TEH BOTOL 220ML | E24: 48 | F24: =G24/E24 -> 2166.6667 | G24: 104000
C25: TEH BOTOL 250ML | E25: 48 | F25: =G25/E25 -> 2500 | G25: 120000
C26: TEH BOTOL 1 LTR | E26: 36 | F26: =G26/E26 -> 7875 | G26: 283500
F27: =G27/E27 -> #DIV/0!
F28: =G28/E28 -> #DIV/0!
F29: =G29/E29 -> #DIV/0!
F30: =G30/E30 -> #DIV/0!
F31: =G31/E31 -> #DIV/0!
F32: =G32/E32 -> #DIV/0!
F33: =G33/E33 -> #DIV/0!
F34: =G34/E34 -> #DIV/0!
F35: =G35/E35 -> #DIV/0!
F36: =G36/E36 -> #DIV/0!
F37: =G37/E37 -> #DIV/0!
C38: FRUITEA | E38: 12 | F38: =G38/E38 -> 3500 | G38: 42000
C39: TEBS | E39: 12 | F39: =G39/E39 -> 3500 | G39: 42000
G40: =SUM(G22:G39) -> 1171653
B41: PT ROCKET CHICKEN INDONESIA | C41: MARINASI | E41: =L14+M15 -> 3.326087 | F41: ='WEEKLY FC'!E324 -> 82362 | G41: =F41*E41 -> 273943.17
G42: =G41 -> 273943.17
L44: =M44/486 -> 0.90123457 | M44: {=SUM(E20:E24+E33:E37)} -> 438
L48: =M48/414 -> 2.826087 | M48: {=SUM(E14:E18+E27:E31)} -> 1170
G49: =G43 -> 0 | L49: =30/60 -> 0.5
A50: 46033 | B50: CELEBES RICE | C50: BERAS | E50: 100 | F50: 14000 | G50: 1400000
G51: =G50 -> 1400000
G53: =G52 -> 0
B54: CV SUKSES BERSAMA | C54: SAOS CHILI | E54: 2500 | F54: =G54/E54 -> 200.9076 | G54: 502269 | L54: =G26+G40+G49+G51+G53+G54+G59+G60+G61 -> 3357422
...

Sheet LPKK
A2: LAPORAN PENGELUARAN KAS KECIL
N4: CABANG : | O4: RC SAMATA GOWA
N5: PERIODE : | O5: 8-14 JANUARI 2025
A8: TGL | B8: NO | C8: BAHAN | D8: BAHAN | E8: BAHAN | F8: BAHAN | G8: BAHAN | H8: MINYAK | I8: GROCERIES / | J8: BAHAN | K8: TRANSPORT | L8: FOTO COPY / | M8: NO ACC | N8: LAIN - LAIN | Q8: SALDO
B9: NOTA | C9: AYAM | D9: PELENGKAP | E9: ES | F9: MINUMAN | G9: PEMBUNGKUS | H9: GORENG | I9: BUMBU | J9: PEMBERSIH | L9: ATK | N9: ( Rp ) | O9: KETERANGAN | P9: JUMLAH
B10: 1 | N10: 4621304 | O10: TRANSFER OWNER CASH | P10: =SUM(C10:N10) -> 4621304
A11: 46030 | B11: 2 | N11: 90300 | O11: XL PRABAYAR | P11: =SUM(C11:N11) -> 90300
B12: 3 | N12: 371300 | O12: WIFI | P12: =SUM(C12:N12) -> 371300
B13: 4 | N13: 203000 | O13: TOKEN LISTRIK | P13: =SUM(C13:N13) -> 203000
B14: 5 | E14: 16000 | O14: ES BATU | P14: =SUM(C14:N14) -> 16000 | Q14: =SUM(P10:P17) -> 5449904
B15: 6 | D15: 5000 | I15: 143000 | O15: SAYURAN | P15: =SUM(C15:N15) -> 148000
P16: =SUM(C16:N16) -> 0
P17: =SUM(C17:N17) -> 0
P18: =SUM(C18:N18) -> 0
P19: =SUM(C19:N19) -> 0
P20: =SUM(C20:N20) -> 0
P21: =SUM(C21:N21) -> 0
N22: ='LAPORAN KAS PERIODE'!C18 -> 221018 | O22: TF OWNER GOFOOD | P22: =SUM(C22:N22) -> 221018
N23: ='LAPORAN KAS PERIODE'!C19 -> 379318 | O23: TF OWNER GRAB FOOD | P23: =SUM(C23:N23) -> 379318 | Q23: =SUM(P22:P25) -> 1892686
N24: ='LAPORAN KAS PERIODE'!C20 -> 349496 | O24: TF OWNER SHOPEE FOOD' | P24: =SUM(C24:N24) -> 349496
N25: ='LAPORAN KAS PERIODE'!C21 -> 942854 | O25: TF OWNER QRIS | P25: =SUM(C25:N25) -> 942854
N26: ='LAPORAN KAS PERIODE'!C24 -> 6647 | O26: ADMIN OVO | P26: =SUM(C26:N26) -> 6647
P27: =SUM(C27:N27) -> 0
P28: =SUM(C28:N28) -> 0
B29: 14 | P29: =SUM(C29:N29) -> 0
B30: 15 | P30: =SUM(C30:N30) -> 0
B31: 16 | P31: =SUM(C31:N31) -> 0
B32: 17 | P32: =SUM(C32:N32) -> 0
B33: 18 | P33: =SUM(C33:N33) -> 0
B34: 19 | P34: =SUM(C34:N34) -> 0
B35: 20 | P35: =SUM(C35:N35) -> 0
B36: 21 | P36: =SUM(C36:N36) -> 0
B37: 22 | P37: =SUM(C37:N37) -> 0
B38: 23 | P38: =SUM(C38:N38) -> 0
B39: 24 | P39: =SUM(C39:N39) -> 0
B40: 25 | P40: =SUM(C40:N40) -> 0
C41: =SUM(C11:C40) -> 0 | D41: =SUM(D11:D40) -> 5000 | E41: =SUM(E11:E40) -> 16000 | F41: =SUM(F11:F40) -> 0 | G41: =SUM(G11:G40) -> 0 | H41: =SUM(H11:H40) -> 0 | I41: =SUM(I11:I40) -> 143000 | J41: =SUM(J11:J40) -> 0 | ... N41: =SUM(N11:N40) -> 2563933 | P41: =SUM(P10:P40) -> 7349237 | Q41: =P41 -> 7349237
A42: 45666 | B42: 7 | D42: 18000 | O42: ROTI TAWAR | P42: =SUM(C42:N42) -> 18000
B43: 8 | D43: 40900 | N43: 200 | O43: BAHAN PATTY | P43: =SUM(C43:N43) -> 41100
B44: 9 | E44: 16000 | O44: ES BATU | P44: =SUM(C44:N44) -> 16000
...

Sheet VENDOR
M2: VENDOR REPORT | AI2: CABANG : | AJ2: =LPKK!O4 -> RC SAMATA GOWA
AI3: PERIODE : | AJ3: =LPKK!O5 -> 8-14 JANUARI 2025 | AQ3: RINCIAN PENCATATAN PEMBELIAN AYAM KREDIT
B5: TGL FAKTUR | C5: NO | E5: PEMAKAIAN | G5: PERSEDIAAN | I5: 46030 | K5: 46031 | M5: 46032 | O5: 46033 | Q5: 46034 | S5: 46035 | U5: 46036 | AC5: KHUSUS TO / TI ( - ) | AE5: KREDIT BARGUD | AG5: KREDIT BAHAN BAKU | AI5: TOTAL | AK5: PERSEDIAAN | AM5: PEMAKAIAN
D6: KETERANGAN BAHAN | E6: MINGGU LALU | G6: AWAL | AC6: C. PATTY / CATERING STAFF ( - ) | AI6: PEMBELIAN | AK6: AKHIR | AM6: MINGGU INI | AP6: TGL FAKTUR
B7: HARI | E7: DLM SATUAN | G7: DLM SATUAN | I7: KAMIS | K7: JUMAT | M7: SABTU | O7: MINGGU | Q7: SENIN | S7: SELASA | U7: RABU | AC7: PERKEDEL / BARGUD | AG7: AYAM DLL | AI7: DLM SATUAN | AK7: DLM SATUAN | AM7: DLM SATUAN | AP7: HARI
E8: Rp | F8: Unit | G8: Rp | H8: Unit | I8: Rp | J8: Unit | K8: Rp | L8: Unit | M8: Rp | N8: Unit | O8: Rp | P8: Unit | Q8: Rp | R8: Unit | S8: Rp | T8: Unit | U8: Rp | V8: Unit | W8: Rp | X8: Unit | Y8: Rp | Z8: Unit | AA8: Rp | AB8: Unit | AC8: Rp | AD8: Unit | AE8: Rp | AF8: Unit | AG8: Rp | AH8: Unit | AI8: Rp | AJ8: Unit | AK8: Rp | AL8: Unit | AM8: Rp | AN8: Unit | AQ8: RP | AR8: UNIT | AS8: RP | AT8: UNIT | AU8: RP | AV8: UNIT | AW8: RP | AX8: UNIT | AY8: RP | AZ8: UNIT | BA8: RP | BB8: UNIT | BC8: RP | BD8: UNIT
D9: AYAM | I9: =SUM(I10:I14) -> 0 | K9: =SUM(K10:K14) -> 0 | M9: =SUM(M10:M14) -> 0 | O9: =SUM(O10:O14) -> 0 | Q9: =SUM(Q10:Q14) -> 0 | S9: =SUM(S10:S14) -> 0 | U9: =SUM(U10:U14) -> 0 | W9: =SUM(W10:W14) -> 0 | Y9: =SUM(Y10:Y14) -> 0 | AA9: =SUM(AA10:AA14) -> 0 | AG9: =SUM(AG10:AG14) -> 6220850 | AI9: =SUM(AI10:AI14) -> 5939783.4 | AP9: AYAM | AQ9: =SUM(AQ10:AQ14) -> 6220850 | AS9: =SUM(AS10:AS14) -> 0 | AU9: =SUM(AU10:AU14) -> 0 | AW9: =SUM(AW10:AW14) -> 0 | AY9: =SUM(AY10:AY14) -> 0 | BA9: =SUM(BA10:BA14) -> 0 | BC9: =SUM(BC10:BC14) -> 0
C10: 1 | D10: ='WEEKLY FC'!B11 -> DADA MENTOK | E10: 1119761.3 | F10: 191.4 | G10: 818584.31 | H10: 133 | AC10: =-'TO - TI'!I20-'TO - TI'!S7 -> -30773.846 | AD10: =-'TO - TI'!Q7-'TO - TI'!G7 -> -12 | AG10: =SUM(AQ10+AS10+AU10+AW10+AY10+BA10+BC10) -> 777606.25 | AH10: =SUM(AR10+AT10+AV10+AX10+AZ10+BB10+BD10) -> 130 | AI10: =SUM(I10,K10,M10,O10,Q10,S10,U10,W10,Y10,AA10,AC10,AE10,AG10) -> 746832.4 | AJ10: =SUM(J10,L10,N10,P10,R10,T10,V10,X10,Z10,AB10,AD10,AF10,AH10) -> 118 | AK10: =('WEEKLY FC'!F11) -> 691180.58 | AL10: ='WEEKLY FC'!D11 -> 112.3 | AM10: =G10+AI10-AK10 -> 874236.13 | AN10: =H10+AJ10-AL10 -> 138.7 | AP10: DADA MENTOK | AQ10: ='PEMBELIAN KREDIT'!G14 -> 777606.25 | AR10: ='PEMBELIAN KREDIT'!E14 -> 130
C11: 2 | D11: ='WEEKLY FC'!B12 -> DADA | E11: 2846596.6 | F11: 391 | G11: 1824273.6 | H11: 247 | AC11: =-'TO - TI'!I7-'TO - TI'!N7 -> -55391.748 | AD11: =-'TO - TI'!G7-'TO - TI'!L7 -> -7 | AG11: =SUM(AQ11+AS11+AU11+AW11+AY11+BA11+BC11) -> 1866255 | AH11: =SUM(AR11+AT11+AV11+AX11+AZ11+BB11+BD11) -> 260 | AI11: =SUM(I11,K11,M11,O11,Q11,S11,U11,W11,Y11,AA11,AC11,AE11,AG11) -> 1810863.3 | AJ11: =SUM(J11,L11,N11,P11,R11,T11,V11,X11,Z11,AB11,AD11,AF11,AH11) -> 253 | AK11: =('WEEKLY FC'!F12) -> 1536230.4 | AL11: ='WEEKLY FC'!D12 -> 208 | AM11: =G11+AI11-AK11 -> 2098906.5 | AN11: =H11+AJ11-AL11 -> 292 | AP11: DADA | AQ11: ='PEMBELIAN KREDIT'!G15 -> 1866255 | AR11: ='PEMBELIAN KREDIT'!E15 -> 260
C12: 3 | D12: ='WEEKLY FC'!B13 -> PAHA ATAS | E12: 2357685.9 | F12: 401 | G12: 1481453 | H12: 249 | AG12: =SUM(AQ12+AS12+AU12+AW12+AY12+BA12+BC12) -> 1503372.1 | AH12: =SUM(AR12+AT12+AV12+AX12+AZ12+BB12+BD12) -> 260 | AI12: =SUM(I12,K12,M12,O12,Q12,S12,U12,W12,Y12,AA12,AC12,AE12,AG12) -> 1503372.1 | AJ12: =SUM(J12,L12,N12,P12,R12,T12,V12,X12,Z12,AB12,AD12,AF12,AH12) -> 260 | AK12: =('WEEKLY FC'!F13) -> 1237518.9 | AL12: ='WEEKLY FC'!D13 -> 208 | AM12: =G12+AI12-AK12 -> 1747306.1 | AN12: =H12+AJ12-AL12 -> 301 | AP12: PAHA ATAS | AQ12: ='PEMBELIAN KREDIT'!G16 -> 1503372.1 | AR12: ='PEMBELIAN KREDIT'!E16 -> 260
C13: 4 | D13: ='WEEKLY FC'!B14 -> PAHA BAWAH | E13: 1451138.1 | F13: 377 | G13: 1064159.2 | H13: 273 | AC13: =-'TO - TI'!S8-'TO - TI'!N9-'TO - TI'!D19 -> -194900.96 | AD13: =-'TO - TI'!Q8-'TO - TI'!L9-'TO - TI'!B19 -> -50 | AG13: =SUM(AQ13+AS13+AU13+AW13+AY13+BA13+BC13) -> 984967.92 | AH13: =SUM(AR13+AT13+AV13+AX13+AZ13+BB13+BD13) -> 260 | AI13: =SUM(I13,K13,M13,O13,Q13,S13,U13,W13,Y13,AA13,AC13,AE13,AG13) -> 790066.96 | AJ13: =SUM(J13,L13,N13,P13,R13,T13,V13,X13,Z13,AB13,AD13,AF13,AH13) -> 210 | AK13: =('WEEKLY FC'!F14) -> 935524.62 | AL13: ='WEEKLY FC'!D14 -> 240 | AM13: =G13+AI13-AK13 -> 918701.59 | AN13: =H13+AJ13-AL13 -> 243 | AP13: PAHA BAWAH | AQ13: ='PEMBELIAN KREDIT'!G17 -> 984967.92 | AR13: ='PEMBELIAN KREDIT'!E17 -> 260
B14: A | C14: 5 | D14: ='WEEKLY FC'!B15 -> SAYAP | E14: 1929424.8 | F14: 453 | G14: 1085701.3 | H14: 252 | AC14: =-'TO - TI'!N10 -> 0 | AD14: =-'TO - TI'!L10 -> 0 | AG14: =SUM(AQ14+AS14+AU14+AW14+AY14+BA14+BC14) -> 1088648.8 | AH14: =SUM(AR14+AT14+AV14+AX14+AZ14+BB14+BD14) -> 260 | AI14: =SUM(I14,K14,M14,O14,Q14,S14,U14,W14,Y14,AA14,AC14,AE14,AG14) -> 1088648.8 | AJ14: =SUM(J14,L14,N14,P14,R14,T14,V14,X14,Z14,AB14,AD14,AF14,AH14) -> 260 | AK14: =('WEEKLY FC'!F15) -> 904751.08 | AL14: ='WEEKLY FC'!D15 -> 210 | AM14: =G14+AI14-AK14 -> 1269599 | AN14: =H14+AJ14-AL14 -> 302 | AP14: SAYAP | AQ14: ='PEMBELIAN KREDIT'!G18 -> 1088648.8 | AR14: ='PEMBELIAN KREDIT'!E18 -> 260
B15: Y | C15: 6 | D15: ='WEEKLY FC'!B16 -> CHICKEN PATTY | E15: 201385.46 | F15: 54 | G15: 22376.162 | H15: 6 | AC15: ='TO - TI'!S21 -> 264706.31 | AD15: ='TO - TI'!Q23 -> 69 | AI15: =SUM(I15,K15,M15,O15,Q15,S15,U15,W15,Y15,AA15,AC15,AE15,AG15) -> 264706.31 | AJ15: =SUM(J15,L15,N15,P15,R15,T15,V15,X15,Z15,AB15,AD15,AF15,AH15) -> 69 | AK15: =('WEEKLY FC'!F16) -> 41022.963 | AL15: ='WEEKLY FC'!D16 -> 11 | AM15: =G15+AI15-AK15 -> 246059.51 | AN15: =H15+AJ15-AL15 -> 64
B16: A | C16: 7 | D16: ='WEEKLY FC'!B17 -> SAYAP TANPA KOLAR | E16: 0 | F16: 0 | G16: 0 | H16: 0 | AI16: =SUM(I16,K16,M16,O16,Q16,S16,U16,W16,Y16,AA16,AC16,AE16,AG16) -> 0 | AJ16: =SUM(J16,L16,N16,P16,R16,T16,V16,X16,Z16,AB16,AD16,AF16,AH16) -> 0 | AK16: =('WEEKLY FC'!F17) -> 0 | AL16: ='WEEKLY FC'!D17 -> 0 | AM16: =G16+AI16-AK16 -> 0 | AN16: =H16+AJ16-AL16 -> 0
B17: M | C17: 8 | D17: ='WEEKLY FC'!B18 -> PATTY BEEF | E17: 0 | F17: 0 | G17: 0 | H17: 0 | AI17: =SUM(I17,K17,M17,O17,Q17,S17,U17,W17,Y17,AA17,AC17,AE17,AG17) -> 0 | AJ17: =SUM(J17,L17,N17,P17,R17,T17,V17,X17,Z17,AB17,AD17,AF17,AH17) -> 0 | AK17: ='WEEKLY FC'!F18 -> 0 | AL17: ='WEEKLY FC'!D18 -> 0 | AM17: =G17+AI17-AK17 -> 0 | AN17: =H17+AJ17-AL17 -> 0 | AP17: NB. RINCIAN PENCATATAN PEMBELIAN AYAM KREDIT TIDAK PERLU DI PRINT
C18: 9 | D18: ='WEEKLY FC'!B19 -> BEEF STEAK | E18: 0 | F18: 0 | G18: 0 | H18: 0 | AI18: =SUM(I18,K18,M18,O18,Q18,S18,U18,W18,Y18,AA18,AC18,AE18,AG18) -> 0 | AJ18: =SUM(J18,L18,N18,P18,R18,T18,V18,X18,Z18,AB18,AD18,AF18,AH18) -> 0 | AK18: ='WEEKLY FC'!F19 -> 0 | AL18: ='WEEKLY FC'!D19 -> 0 | AM18: =G18+AI18-AK18 -> 0 | AN18: =H18+AJ18-AL18 -> 0
C19: 10 | D19: ='WEEKLY FC'!B20 -> DADA MENTOK TAKJIL | E19: 0 | F19: 0 | G19: 0 | H19: 0 | AG19: =SUM(AQ23+AS23+AU23+AW23+AY23+BA23+BC23) -> 0 | AH19: =SUM(AR23+AT23+AV23+AX23+AZ23+BB23+BD23) -> 0 | AI19: =SUM(I19,K19,M19,O19,Q19,S19,U19,W19,Y19,AA19,AC19,AE19,AG19) -> 0 | AJ19: =SUM(J19,L19,N19,P19,R19,T19,V19,X19,Z19,AB19,AD19,AF19,AH19) -> 0 | AK19: ='WEEKLY FC'!F20 -> 0 | AL19: ='WEEKLY FC'!D20 -> 0 | AM19: =G19+AI19-AK19 -> 0 | AN19: =H19+AJ19-AL19 -> 0 | AP19: TGL FAKTUR
C20: 11 | D20: ='WEEKLY FC'!B21 -> DADA TAKJIL | E20: 0 | F20: 0 | G20: 0 | H20: 0 | AG20: =SUM(AQ24+AS24+AU24+AW24+AY24+BA24+BC24) -> 0 | AH20: =SUM(AR24+AT24+AV24+AX24+AZ24+BB24+BD24) -> 0 | AI20: =SUM(I20,K20,M20,O20,Q20,S20,U20,W20,Y20,AA20,AC20,AE20,AG20) -> 0 | AJ20: =SUM(J20,L20,N20,P20,R20,T20,V20,X20,Z20,AB20,AD20,AF20,AH20) -> 0 | AK20: ='WEEKLY FC'!F21 -> 0 | AL20: ='WEEKLY FC'!D21 -> 0 | AM20: =G20+AI20-AK20 -> 0 | AN20: =H20+AJ20-AL20 -> 0 | AP20: HARI
C21: 12 | D21: ='WEEKLY FC'!B22 -> PAHA ATAS TAKJIL | E21: 0 | F21: 0 | G21: 0 | H21: 0 | AG21: =SUM(AQ25+AS25+AU25+AW25+AY25+BA25+BC25) -> 0 | AH21: =SUM(AR25+AT25+AV25+AX25+AZ25+BB25+BD25) -> 0 | AI21: =SUM(I21,K21,M21,O21,Q21,S21,U21,W21,Y21,AA21,AC21,AE21,AG21) -> 0 | AJ21: =SUM(J21,L21,N21,P21,R21,T21,V21,X21,Z21,AB21,AD21,AF21,AH21) -> 0 | AK21: ='WEEKLY FC'!F22 -> 0 | AL21: ='WEEKLY FC'!D22 -> 0 | AM21: =G21+AI21-AK21 -> 0 | AN21: =H21+AJ21-AL21 -> 0 | AQ21: RP | AR21: UNIT | AS21: RP | AT21: UNIT | AU21: RP | AV21: UNIT | AW21: RP | AX21: UNIT | AY21: RP | AZ21: UNIT | BA21: RP | BB21: UNIT | BC21: RP | BD21: UNIT
C22: 13 | D22: ='WEEKLY FC'!B23 -> PAHA BAWAH TAKJIL | E22: 0 | F22: 0 | G22: 0 | H22: 0 | AG22: =SUM(AQ26+AS26+AU26+AW26+AY26+BA26+BC26) -> 0 | AH22: =SUM(AR26+AT26+AV26+AX26+AZ26+BB26+BD26) -> 0 | AI22: =SUM(I22,K22,M22,O22,Q22,S22,U22,W22,Y22,AA22,AC22,AE22,AG22) -> 0 | AJ22: =SUM(J22,L22,N22,P22,R22,T22,V22,X22,Z22,AB22,AD22,AF22,AH22) -> 0 | AK22: ='WEEKLY FC'!F23 -> 0 | AL22: ='WEEKLY FC'!D23 -> 0 | AM22: =G22+AI22-AK22 -> 0 | AN22: =H22+AJ22-AL22 -> 0 | AP22: AYAM | AQ22: =SUM(AQ23:AQ27) -> 0 | AS22: =SUM(AS23:AS27) -> 0 | AU22: =SUM(AU23:AU27) -> 0 | AW22: =SUM(AW23:AW27) -> 0 | AY22: =SUM(AY23:AY27) -> 0 | BA22: =SUM(BA23:BA27) -> 0 | BC22: =SUM(BC23:BC27) -> 0
C23: 14 | D23: ='WEEKLY FC'!B24 -> SAYAP TAKJIL | E23: 0 | F23: 0 | G23: 0 | H23: 0 | AG23: =SUM(AQ27+AS27+AU27+AW27+AY27+BA27+BC27) -> 0 | AH23: =SUM(AR27+AT27+AV27+AX27+AZ27+BB27+BD27) -> 0 | AI23: =SUM(I23,K23,M23,O23,Q23,S23,U23,W23,Y23,AA23,AC23,AE23,AG23) -> 0 | AJ23: =SUM(J23,L23,N23,P23,R23,T23,V23,X23,Z23,AB23,AD23,AF23,AH23) -> 0 | AK23: ='WEEKLY FC'!F24 -> 0 | AL23: ='WEEKLY FC'!D24 -> 0 | AM23: =G23+AI23-AK23 -> 0 | AN23: =H23+AJ23-AL23 -> 0 | AP23: DADA MENTOK TAKJIL
C24: 15 | D24: ='WEEKLY FC'!B25 -> AYAM UTUH | E24: 980000 | F24: 28 | G24: 315000 | H24: 9 | AG24: =SUM(AQ28+AS28+AU28+AW28+AY28+BA28+BC28) -> 1020000 | AH24: =SUM(AR28+AT28+AV28+AX28+AZ28+BB28+BD28) -> 30 | AI24: =SUM(I24,K24,M24,O24,Q24,S24,U24,W24,Y24,AA24,AC24,AE24,AG24) -> 1020000 | AJ24: =SUM(J24,L24,N24,P24,R24,T24,V24,X24,Z24,AB24,AD24,AF24,AH24) -> 30 | AK24: ='WEEKLY FC'!F25 -> 1050000 | AL24: ='WEEKLY FC'!D25 -> 30 | AM24: =G24+AI24-AK24 -> 285000 | AN24: =H24+AJ24-AL24 -> 9 | AP24: DADA TAKJIL
C25: 16 | D25: ='WEEKLY FC'!B30 -> 0 | E25: 0 | F25: 0 | G25: 0 | H25: 0 | AI25: =SUM(I25,K25,M25,O25,Q25,S25,U25,W25,Y25,AA25,AC25,AE25,AG25) -> 0 | AJ25: =SUM(J25,L25,N25,P25,R25,T25,V25,X25,Z25,AB25,AD25,AF25,AH25) -> 0 | AK25: ='WEEKLY FC'!F26 -> 0 | AL25: ='WEEKLY FC'!D26 -> 0 | AM25: =G25+AI25-AK25 -> 0 | AN25: =H25+AJ25-AL25 -> 0 | AP25: PAHA ATAS TAKJIL
C26: 1 | D26: ='WEEKLY FC'!B33 -> VEGETABLE MIX | E26: 34500 | F26: 1.15 | G26: 97500 | H26: 3.25 | AI26: =SUM(I26,K26,M26,O26,Q26,S26,U26,W26,Y26,AA26,AC26,AE26,AG26) -> 0 | AJ26: =SUM(J26,L26,N26,P26,R26,T26,V26,X26,Z26,AB26,AD26,AF26,AH26) -> 0 | AK26: ='WEEKLY FC'!F33 -> 75000 | AL26: ='WEEKLY FC'!D33 -> 2.5 | AM26: =G26+AI26-AK26 -> 22500 | AN26: =H26+AJ26-AL26 -> 0.75 | AP26: PAHA BAWAH TAKJIL
B27: P | C27: 2 | D27: ='WEEKLY FC'!B34 -> BERAS | E27: 1420085.9 | F27: 106.54545 | G27: 826000 | H27: 59 | AC27: =-'TO - TI'!I23-'TO - TI'!N11 -> -126609.71 | AD27: =-'TO - TI'!G23/11 -> -4.7272727 | AG27: ='PEMBELIAN KREDIT'!G50 -> 1400000 | AH27: 100 | AI27: =SUM(I27,K27,M27,O27,Q27,S27,U27,W27,Y27,AA27,AC27,AE27,AG27) -> 1273390.3 | AJ27: =SUM(J27,L27,N27,P27,R27,T27,V27,X27,Z27,AB27,AD27,AF27,AH27) -> 95.272727 | AK27: ='WEEKLY FC'!F34 -> 1092000 | AL27: ='WEEKLY FC'!D34 -> 78 | AM27: =G27+AI27-AK27 -> 1007390.3 | AN27: =H27+AJ27-AL27 -> 76.272727 | AP27: SAYAP TAKJIL
B28: E | C28: 3 | D28: ='WEEKLY FC'!B35 -> FRENCH FRIES | E28: 114400 | F28: 4.4 | G28: 130000 | H28: 5 | AI28: =SUM(I28,K28,M28,O28,Q28,S28,U28,W28,Y28,AA28,AC28,AE28,AG28) -> 0 | AJ28: =SUM(J28,L28,N28,P28,R28,T28,V28,X28,Z28,AB28,AD28,AF28,AH28) -> 0 | AK28: ='WEEKLY FC'!F35 -> 59800 | AL28: ='WEEKLY FC'!D35 -> 2.3 | AM28: =G28+AI28-AK28 -> 70200 | AN28: =H28+AJ28-AL28 -> 2.7 | AP28: AYAM UTUH | AQ28: 1020000 | AR28: 30
B29: L | C29: 4 | D29: ='WEEKLY FC'!B36 -> ROTI BURGER | E29: 278554.33 | F29: 53 | G29: 372106.67 | H29: 128 | AI29: =SUM(I29,K29,M29,O29,Q29,S29,U29,W29,Y29,AA29,AC29,AE29,AG29) -> 0 | AJ29: =SUM(J29,L29,N29,P29,R29,T29,V29,X29,Z29,AB29,AD29,AF29,AH29) -> 0 | AK29: ='WEEKLY FC'!F36 -> 200588.75 | AL29: ='WEEKLY FC'!D36 -> 69 | AM29: =G29+AI29-AK29 -> 171517.92 | AN29: =H29+AJ29-AL29 -> 59
B30: E | C30: 5 | D30: ='WEEKLY FC'!B37 -> SOSIS | E30: 0 | F30: 0 | G30: 0 | H30: 0 | AI30: =SUM(I30,K30,M30,O30,Q30,S30,U30,W30,Y30,AA30,AC30,AE30,AG30) -> 0 | AJ30: =SUM(J30,L30,N30,P30,R30,T30,V30,X30,Z30,AB30,AD30,AF30,AH30) -> 0 | AK30: ='WEEKLY FC'!F37 -> 0 | AL30: ='WEEKLY FC'!D37 -> 0 | AM30: =G30+AI30-AK30 -> 0 | AN30: =H30+AJ30-AL30 -> 0
B31: N | C31: 6 | D31: ='WEEKLY FC'!B38 -> PERKEDEL | E31: 139681.93 | F31: 95 | G31: 10140.264 | H31: 7 | AC31: ='TO - TI'!D20 -> 237571.91 | AD31: ='TO - TI'!B22-4 -> 140 | AI31: =SUM(I31,K31,M31,O31,Q31,S31,U31,W31,Y31,AA31,AC31,AE31,AG31) -> 237571.91 | AJ31: =SUM(J31,L31,N31,P31,R31,T31,V31,X31,Z31,AB31,AD31,AF31,AH31) -> 140 | AK31: ='WEEKLY FC'!F38 -> 118785.95 | AL31: ='WEEKLY FC'!D38 -> 72 | AM31: =G31+AI31-AK31 -> 128926.22 | AN31: =H31+AJ31-AL31 -> 75
B32: G | C32: 7 | D32: ='WEEKLY FC'!B39 -> CRINKLE | E32: 92800 | F32: 2.9 | G32: 60800 | H32: 1.9 | AI32: =SUM(I32,K32,M32,O32,Q32,S32,U32,W32,Y32,AA32,AC32,AE32,AG32) -> 0 | AJ32: =SUM(J32,L32,N32,P32,R32,T32,V32,X32,Z32,AB32,AD32,AF32,AH32) -> 0 | AK32: ='WEEKLY FC'!F39 -> 22400 | AL32: ='WEEKLY FC'!D39 -> 0.7 | AM32: =G32+AI32-AK32 -> 38400 | AN32: =H32+AJ32-AL32 -> 1.2
B33: K | C33: 8 | D33: ='WEEKLY FC'!B40 -> NUGGET COIN | E33: 0 | F33: 0 | G33: 0 | H33: 0 | AI33: =SUM(I33,K33,M33,O33,Q33,S33,U33,W33,Y33,AA33,AC33,AE33,AG33) -> 0 | AJ33: =SUM(J33,L33,N33,P33,R33,T33,V33,X33,Z33,AB33,AD33,AF33,AH33) -> 0 | AK33: ='WEEKLY FC'!F40 -> 0 | AL33: ='WEEKLY FC'!D40 -> 0 | AM33: =G33+AI33-AK33 -> 0 | AN33: =H33+AJ33-AL33 -> 0
B34: A | C34: 9 | D34: ='WEEKLY FC'!B41 -> NUGGET STICK | E34: 0 | F34: 0 | G34: 0 | H34: 0 | AI34: =SUM(I34,K34,M34,O34,Q34,S34,U34,W34,Y34,AA34,AC34,AE34,AG34) -> 0 | AJ34: =SUM(J34,L34,N34,P34,R34,T34,V34,X34,Z34,AB34,AD34,AF34,AH34) -> 0 | AK34: ='WEEKLY FC'!F41 -> 0 | AL34: ='WEEKLY FC'!D41 -> 0 | AM34: =G34+AI34-AK34 -> 0 | AN34: =H34+AJ34-AL34 -> 0
B35: P | C35: 10 | D35: ='WEEKLY FC'!B42 -> SOSIS MINI JUMBO | E35: 0 | F35: 0 | G35: 0 | H35: 0 | AI35: =SUM(I35,K35,M35,O35,Q35,S35,U35,W35,Y35,AA35,AC35,AE35,AG35) -> 0 | AJ35: =SUM(J35,L35,N35,P35,R35,T35,V35,X35,Z35,AB35,AD35,AF35,AH35) -> 0 | AK35: ='WEEKLY FC'!F42 -> 0 | AL35: ='WEEKLY FC'!D42 -> 0 | AM35: =G35+AI35-AK35 -> 0 | AN35: =H35+AJ35-AL35 -> 0
C36: 11 | D36: ='WEEKLY FC'!B43 -> INDOMIE GORENG | E36: 0 | F36: 0 | G36: 0 | H36: 0 | AI36: =SUM(I36,K36,M36,O36,Q36,S36,U36,W36,Y36,AA36,AC36,AE36,AG36) -> 0 | AJ36: =SUM(J36,L36,N36,P36,R36,T36,V36,X36,Z36,AB36,AD36,AF36,AH36) -> 0 | AK36: ='WEEKLY FC'!F43 -> 0 | AL36: ='WEEKLY FC'!D43 -> 0 | AM36: =G36+AI36-AK36 -> 0 | AN36: =H36+AJ36-AL36 -> 0
C37: 12 | D37: ='WEEKLY FC'!B44 -> KERUPUK UDANG | E37: 0 | F37: 0 | G37: 0 | H37: 0 | AI37: =SUM(I37,K37,M37,O37,Q37,S37,U37,W37,Y37,AA37,AC37,AE37,AG37) -> 0 | AJ37: =SUM(J37,L37,N37,P37,R37,T37,V37,X37,Z37,AB37,AD37,AF37,AH37) -> 0 | AK37: ='WEEKLY FC'!F44 -> 0 | AL37: ='WEEKLY FC'!D44 -> 0 | AM37: =G37+AI37-AK37 -> 0 | AN37: =H37+AJ37-AL37 -> 0
C38: 13 | D38: ='WEEKLY FC'!B45 -> BUN BURGER BEEF | E38: 0 | F38: 0 | G38: 0 | H38: 0 | AI38: =SUM(I38,K38,M38,O38,Q38,S38,U38,W38,Y38,AA38,AC38,AE38,AG38) -> 0 | AJ38: =SUM(J38,L38,N38,P38,R38,T38,V38,X38,Z38,AB38,AD38,AF38,AH38) -> 0 | AK38: ='WEEKLY FC'!F45 -> 0 | AL38: ='WEEKLY FC'!D45 -> 0 | AM38: =G38+AI38-AK38 -> 0 | AN38: =H38+AJ38-AL38 -> 0
C39: 14 | D39: ='WEEKLY FC'!B46 -> CHEESE UNTUK BEEF | E39: 0 | F39: 0 | G39: 0 | H39: 0 | AI39: =SUM(I39,K39,M39,O39,Q39,S39,U39,W39,Y39,AA39,AC39,AE39,AG39) -> 0 | AJ39: =SUM(J39,L39,N39,P39,R39,T39,V39,X39,Z39,AB39,AD39,AF39,AH39) -> 0 | AK39: ='WEEKLY FC'!F46 -> 0 | AL39: ='WEEKLY FC'!D46 -> 0 | AM39: =G39+AI39-AK39 -> 0 | AN39: =H39+AJ39-AL39 -> 0
C40: 15 | D40: ='WEEKLY FC'!B47 -> 0 | E40: 0 | F40: 0 | G40: 0 | H40: 0 | AI40: =SUM(I40,K40,M40,O40,Q40,S40,U40,W40,Y40,AA40,AC40,AE40,AG40) -> 0 | AJ40: =SUM(J40,L40,N40,P40,R40,T40,V40,X40,Z40,AB40,AD40,AF40,AH40) -> 0 | AK40: ='WEEKLY FC'!F47 -> 0 | AL40: ='WEEKLY FC'!D47 -> 0 | AM40: =G40+AI40-AK40 -> 0 | AN40: =H40+AJ40-AL40 -> 0
C41: 16 | D41: ='WEEKLY FC'!B48 -> 0 | E41: 0 | F41: 0 | G41: 0 | H41: 0 | AI41: =SUM(I41,K41,M41,O41,Q41,S41,U41,W41,Y41,AA41,AC41,AE41,AG41) -> 0 | AJ41: =SUM(J41,L41,N41,P41,R41,T41,V41,X41,Z41,AB41,AD41,AF41,AH41) -> 0 | AK41: ='WEEKLY FC'!F48 -> 0 | AL41: ='WEEKLY FC'!D48 -> 0 | AM41: =G41+AI41-AK41 -> 0 | AN41: =H41+AJ41-AL41 -> 0
C42: 17 | D42: ='WEEKLY FC'!B49 -> 0 | E42: 0 | F42: 0 | G42: 0 | H42: 0 | AI42: =SUM(I42,K42,M42,O42,Q42,S42,U42,W42,Y42,AA42,AC42,AE42,AG42) -> 0 | AJ42: =SUM(J42,L42,N42,P42,R42,T42,V42,X42,Z42,AB42,AD42,AF42,AH42) -> 0 | AK42: ='WEEKLY FC'!F49 -> 0 | AL42: ='WEEKLY FC'!D49 -> 0 | AM42: =G42+AI42-AK42 -> 0 | AN42: =H42+AJ42-AL42 -> 0
...

Sheet IKHTISAR FOOD COST
A2: LAPORAN IKHTISAR FOOD COST
C5: CABANG : | D5: =LPKK!O4 -> RC SAMATA GOWA
C6: PERIODE: | D6: =LPKK!O5 -> 8-14 JANUARI 2025
B8: FOOD & BEVERAGE | D8: PAPER
A10: PERSEDIAAN AWAL | B10: 17341888 | D10: 11725905
A12: TRANSFER IN (+) =
A13: C. PATTY | B13: ='TO - TI'!S21 -> 264706.31
A14: PERKEDEL MANUAL
A15: PERKEDEL | B15: ='TO - TI'!D20 -> 237571.91
A17: TOTAL TRANSFER IN | B17: =SUM(B12:B15) -> 502278.22 | D17: =SUM(D12:D15) -> 0
A19: PEMBELIAN
A20: PEMBELIAN KREDIT | B20: =VENDOR!AI177 -> 12234546 | D20: =VENDOR!AI178 -> 0
A21: PEMBELIAN KONTAN | B21: =VENDOR!AI179 -> 1105240 | D21: =VENDOR!AI180 -> 75900
A22: TOTAL PEMBELIAN | B22: =B20+B21 -> 13339786 | D22: =D20+D21 -> 75900
A24: JUMLAH YANG TERSEDIA | B24: =B10+B17+B22 -> 31183952 | D24: =D10+D17+D22 -> 11801805
A26: TRANSFER OUT (-) =
A27: TO CATERING STAFF / FREE | B27: ='TO - TI'!I27+'TO - TI'!N23 -> 203305.98
A28: C. PATTY | B28: =B13 -> 264706.31
A29: PERKEDEL | B29: =B15 -> 237571.91
A30: TO AMB MEETING | B30: 26627
A31: PERGANTIAN PRODUK
A33: TOTAL TRANSFER OUT | B33: =SUM(B27:B31) -> 732211.19 | D33: =SUM(D27:D31) -> 0
A35: PERSEDIAAN AKHIR | B35: ='WEEKLY FC'!F362 -> 17074709 | D35: ='WEEKLY FC'!F363 -> 10606588
A37: JUMLAH YANG DIPAKAI | B37: =B24-B33-B35 -> 13377033 | D37: =D24-D33-D35 -> 1195216.8
A38: (%) | B38: =(B37/B47) -> 0.5317753 | D38: =D37/B47 -> 0.047513284
A41: PENJUALAN KOTOR | B41: ='LAPORAN KAS PERIODE'!M8 -> 28127721
A42: KOREKSI (-) | B42: ='LAPORAN KAS PERIODE'!M12 -> 74750
A43: DISCOUNT (-) | B43: ='LAPORAN KAS PERIODE'!M14 -> 270500
A44: KOMISI PENJUALAN ONLINE (-) | B44: ='LAPORAN KAS PERIODE'!M9+'LAPORAN KAS PERIODE'!M10+'LAPORAN KAS PERIODE'!M11 -> 2627048
A45: TAX (-)
A47: PENJUALAN BERSIH | B47: =B41-B42-B43-B44-B45 -> 25155423
A50: JUMLAH BAHAN YANG DIPAKAI | B50: =B37+D37 -> 14572249 | D50: =B50/B51 -> 0.57928858
A51: JUMLAH PENJUALAN BERSIH | B51: =B47 -> 25155423
A54: CATATAN : PENJUALAN BERSIH DIDAPAT DARI PENJUALAN KOTOR - KOREKSI - DISCOUNT
A55: - PENJUALAN DILUAR PRODUK FOOD & BEVERAGES (KOIN KIDDY RIDE, ROCKET KIDS DLL)

Sheet TO - TI
A2: TO / TI PERKEDEL | F2: TO CATTERING STAFF | K2: TO FREE UNDIAN GELEGAR JANUARI | P2: TO / TI CHICKEN PATTY | U2: TO / TI PERKEDEL MANUAL | Z2: TO CATTERING KHUSUS
C3: CABANG : | D3: =LPKK!O4 -> RC SAMATA GOWA | H3: CABANG : | I3: =D3 -> RC SAMATA GOWA | M3: CABANG : | N3: =I3 -> RC SAMATA GOWA | R3: CABANG : | S3: =D3 -> RC SAMATA GOWA | W3: CABANG : | X3: =S3 -> RC SAMATA GOWA | AB3: CABANG :
C4: PERIODE / TGL : | D4: =LPKK!O5 -> 8-14 JANUARI 2025 | H4: PERIODE / TGL : | I4: =D4 -> 8-14 JANUARI 2025 | M4: PERIODE / TGL : | N4: =I4 -> 8-14 JANUARI 2025 | R4: PERIODE / TGL : | S4: =D4 -> 8-14 JANUARI 2025 | W4: PERIODE / TGL : | X4: =S4 -> 8-14 JANUARI 2025 | AB4: PERIODE / TGL :
A6: NAMA BAHAN | B6: QTY | C6: HARGA BELI | D6: TOTAL | F6: NAMA PRODUCT | G6: QTY | H6: HARGA JUAL | I6: TOTAL | K6: NAMA PRODUCT | L6: QTY | M6: HARGA JUAL | N6: TOTAL | P6: NAMA BAHAN | Q6: QTY | R6: HARGA BELI | S6: TOTAL | U6: NAMA BAHAN | V6: QTY | W6: HARGA BELI | X6: TOTAL | Z6: NAMA PRODUCT | AA6: QTY | AB6: HARGA JUAL | AC6: TOTAL
A7: PREMIK KENTANG | B7: =H41 -> 4000 | C7: ='WEEKLY FC'!E330 -> 38055.24 | D7: =B7/1000*C7 -> 152220.96 | F7: DADA | G7: 7 | H7: 13000 | I7: =H7*G7*G27 -> 55391.748 | K7: DADA | M7: 13000 | N7: =L7*M7*L23 -> 0 | P7: DAGING / MENTOK | Q7: 5 | R7: =C8 -> 6154.7692 | S7: =R7*Q7 -> 30773.846 | U7: KENTANG SAYUR | W7: 10000 | X7: =V7/1000*W7 -> 0 | Z7: CHICKEN STRIP | AB7: 10000 | AC7: =AB7*AA7*AA22 -> 0
A8: DAGING AYAM/MENTOK | C8: ='WEEKLY FC'!E11 -> 6154.7692 | D8: =B8*C8 -> 0 | F8: P. ATAS | I8: =H8*G8*G27 -> 0 | K8: P. ATAS | M8: 13000 | N8: =L8*M8*L23 -> 0 | P8: PAHA BAWAH | Q8: 50 | R8: ='WEEKLY FC'!E14 -> 3898.0192 | S8: =R8*Q8 -> 194900.96 | U8: DAGING AYAM/MENTOK | W8: ='WEEKLY FC'!E11 -> 6154.7692 | X8: =V8*W8 -> 0 | Z8: CHICKEN STEAK | AB8: 10000 | AC8: =AB8*AA8*AA22 -> 0
A9: AIR GALON | B9: =H43 -> 6000 | C9: ='WEEKLY FC'!E77 -> 5000 | D9: =B9/19000*C9 -> 1578.9474 | F9: DADA HOT SPICY | I9: =H9*G9*G27 -> 0 | K9: P. BAWAH | M9: 11000 | N9: =L9*M9*L23 -> 0 | P9: DAGING GILING | S9: =R9*Q9 -> 0 | X9: =V9/1000*W9 -> 0 | Z9: CHICKEN BURGER | AB9: 9000 | AC9: =AB9*AA9*AA22 -> 0
A10: BAWANG MERAH | B10: =H45 -> 200 | C10: ='WEEKLY FC'!E303 -> 52000 | D10: =B10/1000*C10 -> 10400 | F10: P. ATAS HOT SPICY | I10: =H10*G10*G27 -> 0 | K10: SAYAP | M10: 10000 | N10: =L10*M10*L23 -> 0 | P10: ROTI TAWAR | Q10: =R46 -> 16 | R10: ='WEEKLY FC'!E62 -> 933 | S10: =R10*Q10 -> 14928 | U10: BAWANG MERAH | W10: ='WEEKLY FC'!E303 -> 52000 | X10: =V10/1000*W10 -> 0 | Z10: NASI GORENG | AB10: 8000 | AC10: =AB10*AA10*AA22 -> 0
A11: BAWANG PUTIH | B11: =H46 -> 50 | C11: ='WEEKLY FC'!E302 -> 52000 | D11: =B11/1000*C11 -> 2600 | F11: DADA SAMBAL GEPREK | I11: =H11*G11*G27 -> 0 | K11: NASI | M11: 4000 | N11: =L11*M11*L23 -> 0 | P11: SUSU ULTRA | Q11: =R45 -> 50 | R11: ='WEEKLY FC'!E65 -> 4700 | S11: =Q11/250*R11 -> 940 | U11: BAWANG PUTIH | W11: ='WEEKLY FC'!E302 -> 52000 | X11: =V11/1000*W11 -> 0 | AB11: 4000 | AC11: =AB11*AA11*AA22 -> 0
A12: PREMIK PERKEDEL | B12: =H48 -> 4 | C12: ='WEEKLY FC'!E342 -> 3108 | D12: =B12*C12 -> 12432 | F12: P. ATAS SAMBAL GEPREK | I12: =H12*G12*G27 -> 0 | K12: ES TEH | M12: =H25 -> 5000 | N12: =L12*M12*L23 -> 0 | P12: BAWANG BOMBAY | Q12: =R41 -> 100 | R12: ='WEEKLY FC'!E58 -> 5000 | S12: =Q12/1000*R12 -> 500 | U12: GARAM | W12: ='WEEKLY FC'!E299 -> 35000 | AB12: 4000 | AC12: =AB12*AA12*AA22 -> 0
A13: BATANG SLEDRI | B13: =H50 -> 500 | C13: ='WEEKLY FC'!E301 -> 42000 | D13: =B13/1000*C13 -> 21000 | F13: DADA SAMBAL GEPREK | I13: =H13*G13*G27 -> 0 | K13: STEE | M13: 5000 | N13: =M13*L13*L23 -> 0 | P13: MARGARIN | Q13: =R43 -> 35 | R13: ='WEEKLY FC'!E60 -> 6100 | S13: =Q13/200*R13 -> 1067.5 | U13: LADA | W13: ='WEEKLY FC'!E300 -> 28100 | AB13: 4000 | AC13: =AB13*AA13*AA22 -> 0
A14: KUNING TELUR | B14: =H51 -> 20 | C14: ='WEEKLY FC'!E320 -> 1867 | D14: =C14*B14 -> 37340 | F14: P. ATAS SAMBAL GEPREK | I14: =H14*G14*G27 -> 0 | N14: =M14*L14*L23 -> 0 | P14: PREMIK C. PATTY | Q14: =R40 -> 1 | R14: ='WEEKLY FC'!E343 -> 6660 | S14: =Q14*R14 -> 6660 | U14: VETSIN | W14: ='WEEKLY FC'!E298 -> 0 | AB14: 4000 | AC14: =AB14*AA14*AA22 -> 0
F15: DADA SAMBAL GEPREK | I15: =H15*G15*G27 -> 0 | N15: =M15*L15*L23 -> 0 | P15: TELUR | Q15: =R44 -> 8 | R15: =C14 -> 1867 | S15: =Q15*R15 -> 14936 | U15: BATANG SLEDRI | W15: ='WEEKLY FC'!E301 -> 42000 | X15: =V15/1000*W15 -> 0 | AC15: =AB15*AA15*AA22 -> 0
F16: P. ATAS SAMBAL GEPREK | I16: =H16*G16*G27 -> 0 | N16: =M16*L16*L23 -> 0 | U16: KUNING TELUR | W16: ='WEEKLY FC'!E320 -> 1867 | X16: =V16*W16 -> 0 | AC16: =AB16*AA16*AA22 -> 0
F17: DADA CHEESE LEVEL | I17: =H17*G17*G27 -> 0 | N17: =M17*L17*L24 -> 0
F18: P. ATAS CHEESE LEVEL | I18: =H18*G18*G27 -> 0 | N18: =M18*L18*L25 -> 0
A19: PAHA BAWAH | C19: ='WEEKLY FC'!E14 -> 3898.0192 | D19: =C19*B19 -> 0 | F19: CHICKEN STRIP | I19: =H19*G19*G27 -> 0 | N19: =M19*L19*L23 -> 0 | AC19: =AB19*AA19*AA22 -> 0
C20: SUB TOTAL | D20: =SUM(D7:D19) -> 237571.91 | F20: CHICKEN STEAK | H20: ='LAP. PENJUALAN '!S207 -> 14000 | I20: =H20*G20*G27 -> 0 | N20: =M20*L20*L23 -> 0 | W20: SUB TOTAL | X20: =SUM(X7:X19) -> 0 | AC20: =AB20*AA20*AA22 -> 0
F21: CHICKEN BURGER | I21: =H21*G21*G27 -> 0 | N21: =M21*L21*L23 -> 0 | R21: SUB TOTAL | S21: =SUM(S7:S20) -> 264706.31 | AC21: =AB21*AA21*AA22 -> 0
A22: PERKEDEL JADI | B22: 144 | C22: HPP | D22: =D20/B22 -> 1649.8049 | F22: NASI GORENG | I22: =H22*G22*G27 -> 0 | U22: PERKEDEL JADI | W22: HPP | X22: =X20/V22 -> #DIV/0! | Z22: FOOD COST | AA22: =H36 -> 0.60870053 | AC22: =SUM(AC7:AC21) -> 0
F23: NASI | G23: 52 | H23: 4000 | I23: =H23*G23*G27 -> 126609.71 | K23: FOOD COST | L23: =H36 -> 0.60870053 | M23: TOTAL | N23: =SUM(N7:N22) -> 0 | P23: CHICKEN PATTY JADI | Q23: 69 | S23: =S21/Q23 -> 3836.3233
F24: LEMON TEA | I24: =H24*G24*G27 -> 0
F25: ES TEH | G25: 7 | H25: 5000 | I25: =H25*G25*G27 -> 21304.518
I26: =H26*G26*G26 -> 0
D27: PARAF | F27: FOOD COST | G27: =H36 -> 0.60870053 | I27: =SUM(I7:I26) -> 203305.98 | N27: PARAF | S27: PARAF | X27: PARAF | AC27: PARAF
I29: PARAF
D30: (..........................) | X30: (..........................)
N31: (.........................) | S31: (..........................) | U31: NB. DIKERJAKAN MANUAL TANPA RUMUS | AC31: (.........................)
I33: (.........................)
A34: BUAT BERAPA RESEP | B34: 4 | P34: BUAT BERAPA RESEP | Q34: 1
F36: FOOD COST PERIODE KEMARIN | H36: 0.60870053
A37: TOLONG DIBACA SEBELUM MENGISI TO/TI | P37: RUMUS C. PATTY
A39: CATATAN : | F39: RUMUS PERKEDEL
A40: 1. TO/TI PERKEDEL TINGGAL MENGISI MANUAL KOLOM | P40: PREMIK PATTY | Q40: 1 | R40: =Q40*Q34 -> 1
A41: BUAT BERPA RESEP DAN PERKEDEL JADI . | F41: PREMIK KENTANG | G41: 1000 | H41: =G41*B34 -> 4000 | P41: BAWANG BOMBAY | Q41: 100 | R41: =Q41*Q34 -> 100
A42: 2. TO/TI PERKEDEL KOLOM AYAM DI ISI MANUAL | F42: DAGING AYAM/MENTOK | H42: =G42*B34 -> 0
A43: 3. TO FREE DIISI MANUAL | F43: AIR GALON | G43: 1500 | H43: =G43*B34 -> 6000 | P43: MARGARIN | Q43: 35 | R43: =Q43*Q34 -> 35
A44: 4. FOOD COST PERIODE KEMARIN DIISI DAN DISESUAIKAN | P44: TELUR | Q44: 8 | R44: =Q44*Q34 -> 8
A45: 5. TO CATTERING STAFF DIISI MANUAL | F45: BAWANG MERAH | G45: 50 | H45: =G45*B34 -> 200 | P45: SUSU ULTRA | Q45: 50 | R45: =Q45*Q34 -> 50
A46: 6. TO/TI CHICKEN PATTY DIISI MANUAL PAHA BAWAH ATAU | F46: BAWANG PUTIH | G46: 12.5 | H46: =G46*B34 -> 50 | P46: ROTI TAWAR | Q46: 16 | R46: =Q46*Q34 -> 16
...

Sheet HITUNGAN HPP PRODUK
L3: FOOD COST ITEM
Z7: PAKET GEPREK ES THE KELAS 3 & 4 SULAWESI | AS7: PAKET HOT CHESE STEE KELAS 2,3&4 SULAWESI | AZ7: PAKET HOT CHESE THE RC KELAS 2,3&4 SULAWESI
A8: AIR GALON | D8: DADA | G8: SAOS STEAK | J8: PAKET SEGAR KELAS 2,3&4 SULAWESI ES THE POCI | AR8: OKE | AY8: OKE | BF8: OKE
A9: 1 LITER | B9: ='WEEKLY FC'!E77/19 -> 263.15789 | D9: 1 PCS DADA | E9: ='WEEKLY FC'!E12 -> 7385.7231 | G9: 1 PACK PREMIX STEAK ( 200 GR ) | H9: ='WEEKLY FC'!E327 -> 17094 | X9: OKE
A10: ES BATU ( 1 GRAM ) | B10: ='WEEKLY FC'!E78/10000 -> 1.6 | D10: MARINADE | E10: ='WEEKLY FC'!E324/414 -> 198.94203 | G10: AIR (1200 ML) | H10: =B9*1.2 -> 315.78947 | AS10: PAKET | AU10: PAKET | AW10: PAKET | AZ10: PAKET | BB10: PAKET | BD10: PAKET
D11: TEPUNG CAKRA | E11: =('WEEKLY FC'!E331*7)/200 -> 327.705 | J11: PAKET | L11: PAKET | N11: PAKET | P11: PAKET | R11: PAKET | T11: PAKET | V11: PAKET | Z11: PAKET | AB11: PAKET | AD11: PAKET | AF11: PAKET | AH11: PAKET | AJ11: PAKET | AL11: PAKET | AN11: PAKET | AP11: PAKET | AS11: LEVEL 1 | AU11: LEVEL 2 | AW11: LEVEL 3 | AZ11: LEVEL 1 | BB11: LEVEL 2 | BD11: LEVEL 3
D12: TEPUNG BRIDER | E12: =(('WEEKLY FC'!E325*2)/200) -> 234.1 | G12: HPP 1 RESEP | H12: =H9+H10 -> 17409.789 | J12: SEGAR 1 | L12: SEGAR 2 | N12: SEGAR 3 | P12: SEGAR 4 | R12: SEGAR 5 | T12: SEGAR 6 | V12: SEGAR 7 | Z12: GEPREK 1 | AB12: GEPREK 2 | AD12: GEPREK 3 | AF12: MATAH 1 | AH12: MATAH 2 | AJ12: MATAH 3 | AL12: TERASI 1 | AN12: TERASI 2 | AP12: TERASI 3 | AS12: NASI | AT12: =W41 -> 1301.4354 | AU12: NASI | AV12: =Y41 -> 1301.4354 | AW12: NASI | AX12: =AA41 -> 1301.4354 | AZ12: NASI | BA12: =AT12 -> 1301.4354 | BB12: NASI | BC12: =AV12 -> 1301.4354 | BD12: NASI | BE12: =AX12 -> 1301.4354
A13: SIMPLE SIRUP | D13: MINYAK | E13: ='WEEKLY FC'!E168/33 -> 606.10227 | G13: HPP 1 PORSI | H13: =H12/12 -> 1450.8158 | J13: NASI | K13: =H63 -> 954.38596 | L13: NASI | M13: =K13 -> 954.38596 | N13: BURGER | O13: =H138 -> 8292.1367 | P13: NASI | Q13: =K13 -> 954.38596 | R13: PEMBUNGKUS | S13: =E186 -> 1450.5 | T13: NASI | U13: =K13 -> 954.38596 | V13: NASI | W13: =K13 -> 954.38596 | Z13: NASI | AA13: =W13 -> 954.38596 | AB13: NASI | AC13: =AA13 -> 954.38596 | AD13: NASI | AE13: =AC13 -> 954.38596 | AF13: NASI | AG13: =AE13 -> 954.38596 | AH13: NASI | AI13: =AG13 -> 954.38596 | AJ13: NASI | AK13: =AI13 -> 954.38596 | AL13: NASI | AM13: =AK13 -> 954.38596 | AN13: NASI | AO13: =AM13 -> 954.38596 | AP13: NASI | AQ13: =AO13 -> 954.38596 | AS13: SAYAP | AT13: =W42 -> 5698.4354 | AU13: P.BAWAH | AV13: =Y42 -> 5288.1162 | AW13: DADA/PA | AX13: =AA42 -> 8775.82 | AZ13: SAYAP | BA13: =AT13 -> 5698.4354 | BB13: P.BAWAH | BC13: =AV13 -> 5288.1162 | BD13: DADA/PA | BE13: =AX13 -> 8775.82
A14: 1 KG GULA | B14: ='WEEKLY FC'!E72 -> 17600 | D14: AIR | E14: =(B9*1.75)/200 -> 2.3026316 | J14: SAYAP | K14: =E56 -> 6105.4354 | L14: C.STEAK | M14: =E75 -> 8145.877 | N14: ES TEH | O14: =K15 -> 878.01535 | P14: P.BAWAH | Q14: =E43 -> 5695.1162 | R14: NASGOR | S14: =H90 -> 5769.6704 | T14: C.STRIP | U14: =E111 -> 5472.3985 | V14: DADA / PA | W14: =E17 -> 9182.82 | Z14: SAYAP | AA14: =E57 -> 5698.4354 | AB14: P.BAWAH | AC14: =E44 -> 5288.1162 | AD14: DADA | AE14: =E18 -> 8775.82 | AF14: SAYAP GPRK | AG14: =AA14 -> 5698.4354 | AH14: P.BAWAH | AI14: =AC14 -> 5288.1162 | AJ14: DADA/PA | AK14: =AE14 -> 8775.82 | AL14: SAYAP | AM14: =AG14 -> 5698.4354 | AN14: P.BAWAH | AO14: =AI14 -> 5288.1162 | AP14: DADA/PA | AQ14: =AK14 -> 8775.82 | AS14: STEE | AT14: =M95 -> 3500 | AU14: STEE | AV14: =AT14 -> 3500 | AW14: STEE | AX14: =AV14 -> 3500 | AZ14: THE RC | BA14: =B301 -> 219.21053 | BB14: THE RC | BC14: =BA14 -> 219.21053 | BD14: THE RC | BE14: =BC14 -> 219.21053
A15: 1 LITER AIR | B15: =B9 -> 263.15789 | D15: SAOS SASET | E15: ='WEEKLY FC'!E334+'WEEKLY FC'!E335 -> 407 | G15: CHESSEE MELT | J15: ES TEH | K15: =B128 -> 878.01535 | L15: ES TEH | M15: =K15 -> 878.01535 | N15: PEMBUNGKUS | O15: =E177 -> 1130 | P15: ES TEH | Q15: =K15 -> 878.01535 | R15: ES TEH | S15: =K15 -> 878.01535 | T15: ES TEH | U15: =S15 -> 878.01535 | V15: ES TEH | W15: =U15 -> 878.01535 | Z15: ES TEH | AA15: =K15 -> 878.01535 | AB15: ES TEH | AC15: =AA15 -> 878.01535 | AD15: ES TEH | AE15: =AC15 -> 878.01535 | AF15: ES TEH | AG15: =AC15 -> 878.01535 | AH15: ES TEH | AI15: =AG15 -> 878.01535 | AJ15: ES TEH | AK15: =AI15 -> 878.01535 | AL15: ES TEH | AM15: =AG15 -> 878.01535 | AN15: ES TEH | AO15: =AM15 -> 878.01535 | AP15: ES TEH | AQ15: =AO15 -> 878.01535 | AS15: C LEVEL + CM | AT15: =W44 -> 1282.2658 | AU15: C LEVEL + CM | AV15: =AT15 -> 1282.2658 | AW15: C LEVEL + CM | AX15: =AV15 -> 1282.2658 | AZ15: C LEVEL + CM | BA15: =AT15 -> 1282.2658 | BB15: C LEVEL + CM | BC15: =AV15 -> 1282.2658 | BD15: C LEVEL + CM | BE15: =BC15 -> 1282.2658
D16: BIANG BRIDER | E16: =('WEEKLY FC'!E344*1)/200 -> 20.945 | G16: 1 PACK CHESSE MELT ( 100 GR ) | H16: ='WEEKLY FC'!E338 -> 12937 | J16: PEMBUNGKUS | K16: =E204 -> 1555.36 | L16: PEMBUNGKUS | M16: =K16 -> 1555.36 | P16: PEMBUNGKUS | Q16: =M16 -> 1555.36 | R16: HPP NON CVR | S16: =S14+S15 -> 6647.6857 | T16: PEMBUNGKUS | U16: =K16 -> 1555.36 | V16: PEMBUNGKUS | W16: =K16 -> 1555.36 | Z16: GPRK | AA16: =H51 -> 897.4976 | AB16: GPRK | AC16: =AA16 -> 897.4976 | AD16: GPRK | AE16: =AC16 -> 897.4976 | AF16: MATAH | AG16: =E135 -> 1686.4853 | AH16: MATAH | AI16: =AG16 -> 1686.4853 | AJ16: MATAH | AK16: =AI16 -> 1686.4853 | AL16: TRASI | AM16: =E150 -> 1473.3767 | AN16: TRASI | AO16: =AM16 -> 1473.3767 | AP16: TRASI | AQ16: =AO16 -> 1473.3767 | AS16: PEMBUNGKUS | AT16: =W45 -> 2003.36 | AU16: PEMBUNGKUS | AV16: =AT16 -> 2003.36 | AW16: PEMBUNGKUS | AX16: =AV16 -> 2003.36 | AZ16: PEMBUNGKUS | BA16: =AT16 -> 2003.36 | BB16: PEMBUNGKUS | BC16: =AV16 -> 2003.36 | BD16: PEMBUNGKUS | BE16: =BC16 -> 2003.36
A17: HPP 1 RESEP ( 1500 ML ) | B17: =SUM(B13:B15) -> 17863.158 | D17: HPP DADA | E17: =SUM(E9:E16) -> 9182.82 | G17: AIR (400 ML ) | H17: =B9*0.4 -> 105.26316 | J17: HPP NON CVR | K17: =SUM(K13:K15) -> 7937.8367 | L17: HPP NON CVR | M17: =SUM(M13:M15) -> 9978.2783 | N17: HPP NON CVR | O17: =O13+O14 -> 9170.152 | P17: HPP NON CVR | Q17: =SUM(Q13:Q15) -> 7527.5175 | R17: HPP + COVER | S17: =S16+S13 -> 8098.1857 | T17: HPP NON CVR | U17: =SUM(U13:U16) -> 8860.1598 | V17: HPP NON CVR | W17: =SUM(W13:W15) -> 11015.221 | Z17: PEMBUNGKUS | AA17: =E168 -> 1555.36 | AB17: PEMBUNGKUS | AC17: =AA17 -> 1555.36 | AD17: PEMBUNGKUS | AE17: =AC17 -> 1555.36 | AF17: PEMBUNGKUS | AG17: =AE17 -> 1555.36 | AH17: PEMBUNGKUS | AI17: =AG17 -> 1555.36 | AJ17: PEMBUNGKUS | AK17: =AI17 -> 1555.36 | AL17: PEMBUNGKUS | AM17: =AK17 -> 1555.36 | AN17: PEMBUNGKUS | AO17: =AM17 -> 1555.36 | AP17: PEMBUNGKUS | AQ17: =AO17 -> 1555.36 | AS17: HPP NON CVR | AT17: =SUM(AT12:AT15) -> 11782.137 | AU17: HPP NON CVR | AV17: =SUM(AV12:AV15) -> 11371.817 | AW17: HPP NON CVR | AX17: =SUM(AX12:AX15) -> 14859.521 | AZ17: HPP NON CVR | BA17: =SUM(BA12:BA15) -> 8501.3471 | BB17: HPP NON CVR | BC17: =SUM(BC12:BC15) -> 8091.0279 | BD17: HPP NON CVR | BE17: =SUM(BE12:BE15) -> 11578.732
A18: HPP 1 LITER | B18: =(B17/1.5) -> 11908.772 | D18: HPP DADA U/GPRK & LVL | E18: =E17-E15 -> 8775.82 | J18: HPP + COVER | K18: =K17+K16 -> 9493.1967 | L18: HPP + COVER | M18: =M17+M16 -> 11533.638 | N18: HPP + COVER | O18: =O17+O15 -> 10300.152 | P18: HPP + COVER | Q18: =Q17+Q16 -> 9082.8775 | T18: HPP + COVER | V18: HPP + COVER | W18: =W17+W16 -> 12570.581 | Z18: HPP NON CVR | AA18: =SUM(AA13:AA16) -> 8428.3343 | AB18: HPP NON CVR | AC18: =SUM(AC13:AC17) -> 9573.3751 | AD18: HPP NON CVR | AE18: =SUM(AE13:AE16) -> 11505.719 | AF18: HPP NON CVR | AG18: =SUM(AG13:AG16) -> 9217.322 | AH18: HPP NON CVR | AI18: =SUM(AI13:AI16) -> 8807.0028 | AJ18: HPP NON CVR | AK18: =SUM(AK13:AK16) -> 12294.707 | AL18: HPP NON CVR | AM18: =SUM(AM13:AM16) -> 9004.2134 | AN18: HPP NON CVR | AO18: =SUM(AO13:AO16) -> 8593.8942 | AP18: HPP NON CVR | AQ18: =SUM(AQ13:AQ16) -> 12081.598 | AS18: HPP + COVER | AT18: =AT17+AT16 -> 13785.497 | AU18: HPP + COVER | AV18: =AV17+AV16 -> 13375.177 | AW18: HPP + COVER | AX18: =AX17+AX16 -> 16862.881 | AZ18: HPP + COVER | BA18: =BA17+BA16 -> 10504.707 | BB18: HPP + COVER | BC18: =BC17+BC16 -> 10094.388 | BD18: HPP + COVER | BE18: =BE17+BE16 -> 13582.092
Z19: HPP + COVER | AA19: =AA18+AA17 -> 9983.6943 | AB19: HPP + COVER | AC19: =AC18+AC17 -> 11128.735 | AD19: HPP + COVER | AE19: =AE18+AE17 -> 13061.079 | AF19: HPP + COVER | AG19: =AG18+AG17 -> 10772.682 | AH19: HPP + COVER | AI19: =AI18+AI17 -> 10362.363 | AJ19: HPP + COVER | AK19: =AK18+AK17 -> 13850.067 | AL19: HPP + COVER | AM19: =AM18+AM17 -> 10559.573 | AN19: HPP + COVER | AO19: =AO18+AO17 -> 10149.254 | AP19: HPP + COVER | AQ19: =AQ18+AQ17 -> 13636.958
G20: HPP 1 RESEP | H20: =SUM(H16:H18) -> 13042.263
A21: BIANG TEH POCI KUNING | D21: P.ATAS | G21: HPP 1 PORSI | H21: =H20/20 -> 652.11316
A22: 40 GR POCI KUNING | B22: ='WEEKLY FC'!E110 -> 2814 | D22: 1 PCS P.ATAS | E22: ='WEEKLY FC'!E13 -> 5949.6103 | J22: PAKET ROCKET KELAS 3 & 2 KALBAR | Z22: PAKET SEHAT KELAS 3 & 2 KALBAR | AJ22: PAKET CATT KELAS 2,3&4 SULAWESI | AS22: PAKET SEGAR KELAS 2,3&4 SULAWESI STEE
A23: 4 LITER AIR | B23: =B9*4 -> 1052.6316 | D23: MARINADE | E23: =E10 -> 198.94203 | G23: SAOS LEVEL 1 & 2 | X23: OKE | AH23: OKE | AR23: OKE | BG23: OKE
D24: TEPUNG CAKRA | E24: =E11 -> 327.705 | G24: LEVEL(500 GR ) | H24: ='WEEKLY FC'!E336 -> 37296
A25: HPP 1 RESEP | B25: =SUM(B22:B24) -> 3866.6316 | D25: TEPUNG BRIDER | E25: =E12 -> 234.1 | G25: AIR (1.900 ML ) | H25: =B9*1.95 -> 513.15789 | J25: PAKET | L25: PAKET | N25: PAKET | P25: PAKET | R25: PAKET | T25: PAKET | V25: PAKET | Z25: PAKET | AB25: PAKET | AD25: PAKET | AF25: PAKET | AJ25: PAKET | AL25: PAKET | AN25: PAKET | AP25: PAKET | AS25: PAKET | AU25: PAKET | AW25: PAKET | AY25: PAKET | BA25: PAKET | BC25: PAKET | BE25: PAKET
A26: HPP 1 PORSI | B26: =B25/16 -> 241.66447 | D26: MINYAK | E26: =E13 -> 606.10227 | J26: ROCKET 1 | L26: ROCKET 2 | N26: ROCKET 3 | P26: ROCKET 4 | R26: ROCKET 5 | T26: ROCKET 6 | V26: ROCKET 7 | Z26: SEHAT 1 | AB26: SEHAT 2 | AD26: SEHAT 3 | AF26: SEHAT 4 | AJ26: CATT 1 | AL26: CATT 2 | AN26: CATT 3 | AP26: CATT 4 | AS26: SEGAR 1 | AU26: SEGAR 2 | AW26: SEGAR 3 | AY26: SEGAR 4 | BA26: SEGAR 5 | BC26: SEGAR 6 | BE26: SEGAR 7
D27: AIR | E27: =E14 -> 2.3026316 | G27: HPP 1 RESEP | H27: =SUM(H24:H26) -> 37809.158 | J27: NASI | K27: =H61 -> 1301.4354 | L27: NASI | M27: =K27 -> 1301.4354 | N27: BURGER | O27: =H151 -> 8484.1367 | P27: NASI | Q27: =K27 -> 1301.4354 | R27: PEMBUNGKUS | S27: =S13 -> 1450.5 | T27: NASI | U27: =K27 -> 1301.4354 | V27: NASI | W27: =K27 -> 1301.4354 | Z27: NASI | AA27: =W27 -> 1301.4354 | AD27: NASI | AE27: =AA27 -> 1301.4354 | AF27: NASI | AG27: =AA27 -> 1301.4354 | AJ27: NASI | AK27: =AG27 -> 1301.4354 | AL27: NASI | AM27: =AK27 -> 1301.4354 | AN27: NASI | AO27: =AM27 -> 1301.4354 | AP27: NASI | AQ27: =AK27 -> 1301.4354 | AS27: NASI | AT27: =K13 -> 954.38596 | AU27: NASI | AV27: =M13 -> 954.38596 | AW27: BURGER | AX27: =O13 -> 8292.1367 | AY27: NASI | AZ27: =Q13 -> 954.38596 | BA27: PEMBUNGKUS | BB27: =S13 -> 1450.5 | BC27: NASI | BD27: =U13 -> 954.38596 | BE27: NASI | BF27: =W13 -> 954.38596
A28: BIANG TEH POCI VANILA | D28: SAOS SASET | E28: =E15 -> 407 | G28: HPP 1 PORSI | H28: =H27/60 -> 630.15263 | J28: SAYAP | K28: =E56 -> 6105.4354 | L28: C.STEAK | M28: =M14 -> 8145.877 | N28: NESTLE | O28: =K29 -> 1657.4478 | P28: P.BAWAH | Q28: =Q14 -> 5695.1162 | R28: NASGOR | S28: =S14 -> 5769.6704 | T28: C.STRIP | U28: =U14 -> 5472.3985 | V28: DADA / PA | W28: =E30 -> 7746.7072 | Z28: SAYAP | AA28: =K28 -> 6105.4354 | AB28: BURGER | AC28: =O27 -> 8484.1367 | AD28: DADA | AE28: =W28 -> 7746.7072 | AF28: C.STRIP | AG28: =U28 -> 5472.3985 | AJ28: SAYAP/PB | AK28: =AA28 -> 6105.4354 | AL28: DADA/PA | AM28: =AE28 -> 7746.7072 | AN28: SAYAP/PB | AO28: =AK28 -> 6105.4354 | AP28: DADA/PA | AQ28: =AM28 -> 7746.7072 | AS28: SAYAP | AT28: =K14 -> 6105.4354 | AU28: C.STEAK | AV28: =M14 -> 8145.877 | AW28: STEE | AX28: =AV29 -> 3500 | AY28: P.BAWAH | AZ28: =Q14 -> 5695.1162 | BA28: NASGOR | BB28: =S14 -> 5769.6704 | BC28: C.STRIP | BD28: =U14 -> 5472.3985 | BE28: DADA / PA | BF28: =W14 -> 9182.82
D29: BIANG BRIDER | E29: =E16 -> 20.945 | J29: NESTLE | K29: =B45 -> 1657.4478 | L29: NESTLE | M29: =K29 -> 1657.4478 | N29: PEMBUNGKUS | O29: =O15 -> 1130 | P29: NESTLE | Q29: =K29 -> 1657.4478 | R29: NESTLE | S29: =Q29 -> 1657.4478 | T29: NESTEA | U29: =K29 -> 1657.4478 | V29: NESTEA | W29: =U29 -> 1657.4478 | Z29: MILO | AA29: =B70 -> 3136.7994 | AB29: MILO | AC29: =AA29 -> 3136.7994 | AD29: MILO | AE29: =AC29 -> 3136.7994 | AF29: MILO | AG29: =AA29 -> 3136.7994 | AN29: AMB | AO29: ='WEEKLY FC'!E119 -> 3500 | AP29: AMB | AQ29: =AO29 -> 3500 | AS29: STEE | AT29: =AT14 -> 3500 | AU29: STEE | AV29: =AT29 -> 3500 | AW29: PEMBUNGKUS | AX29: =O15 -> 1130 | AY29: STEE | AZ29: =AX28 -> 3500 | BA29: STEE | BB29: =AZ29 -> 3500 | BC29: STEE | BD29: =BB29 -> 3500 | BE29: STEE | BF29: =BD29 -> 3500
A30: 50 GR POCI VANILA | B30: ='WEEKLY FC'!E110 -> 2814 | D30: HPP P.ATAS | E30: =SUM(E22:E29) -> 7746.7072 | J30: PEMBUNGKUS | K30: =E204 -> 1555.36 | L30: PEMBUNGKUS | M30: =K30 -> 1555.36 | P30: PEMBUNGKUS | Q30: =K30 -> 1555.36 | T30: PEMBUNGKUS | U30: =K30 -> 1555.36 | V30: PEMBUNGKUS | W30: =U30 -> 1555.36 | Z30: PEMBUNGKUS | AA30: =W31 -> 10705.59 | AB30: PEMBUNGKUS | AC30: =O29 -> 1130 | AD30: PEMBUNGKUS | AE30: =AA30 -> 10705.59 | AF30: PEMBUNGKUS | AG30: =AA30 -> 10705.59 | AJ30: PEMBUNGKUS | AK30: =SUM(E198:E199)+E203 -> 1135.36 | AL30: PEMBUNGKUS | AM30: =AK30 -> 1135.36 | AN30: PEMBUNGKUS | AO30: =AM30 -> 1135.36 | AP30: PEMBUNGKUS | AQ30: =AO30 -> 1135.36 | AS30: PEMBUNGKUS | AT30: =K16 -> 1555.36 | AU30: PEMBUNGKUS | AV30: =M16 -> 1555.36 | AY30: PEMBUNGKUS | AZ30: =Q16 -> 1555.36 | BA30: HPP NON CVR | BB30: =BB27+BB28 -> 7220.1704 | BC30: PEMBUNGKUS | BD30: =U16 -> 1555.36 | BE30: PEMBUNGKUS | BF30: =W16 -> 1555.36
A31: 8000 ML AIR | B31: =B9*8 -> 2105.2632 | G31: BUTTER MIX | J31: HPP NON CVR | K31: =SUM(K27:K30) -> 10619.679 | L31: HPP NON CVR | M31: =SUM(M27:M29) -> 11104.76 | N31: HPP NON CVR | O31: =O27+O28 -> 10141.584 | P31: HPP NON CVR | Q31: =SUM(Q27:Q29) -> 8653.9994 | R31: HPP NON CVR | S31: =S28+S29 -> 7427.1181 | T31: HPP NON CVR | U31: =SUM(U27:U29) -> 8431.2817 | V31: HPP NON CVR | W31: =SUM(W27:W29) -> 10705.59 | Z31: HPP NON CVR | AA31: =SUM(AA27:AA29) -> 10543.67 | AB31: HPP NON CVR | AC31: =AC28+AC29 -> 11620.936 | AD31: HPP NON CVR | AE31: =SUM(AE27:AE29) -> 12184.942 | AF31: HPP NON CVR | AG31: =SUM(AG27:AG29) -> 9910.6333 | AJ31: HPP NON CVR | AK31: =AK27+AK28 -> 7406.8708 | AL31: HPP NON CVR | AM31: =AM27+AM28 -> 9048.1426 | AN31: HPP NON CVR | AO31: =AO27+AO28+AO29 -> 10906.871 | AP31: HPP NON CVR | AQ31: =AQ27+AQ28+AQ29 -> 12548.143 | AS31: HPP NON CVR | AT31: =SUM(AT27:AT29) -> 10559.821 | AU31: HPP NON CVR | AV31: =SUM(AV27:AV29) -> 12600.263 | AW31: HPP NON CVR | AX31: =AX27+AX28 -> 11792.137 | AY31: HPP NON CVR | AZ31: =SUM(AZ27:AZ29) -> 10149.502 | BA31: HPP + COVER | BB31: =BB30+BB29 -> 10720.17 | BC31: HPP NON CVR | BD31: =SUM(BD27:BD29) -> 9926.7844 | BE31: HPP NON CVR | BF31: =SUM(BF27:BF29) -> 13637.206
G32: 1 PCK BUTTER MIX ( 125 GR ) | H32: ='WEEKLY FC'!E326 -> 8547 | J32: HPP + COVER | K32: =K30+K31 -> 12175.039 | L32: HPP + COVER | M32: =M31+M30 -> 12660.12 | N32: HPP + COVER | O32: =O31+O29 -> 11271.584 | P32: HPP + COVER | Q32: =Q31+Q30 -> 10209.359 | R32: HPP + COVER | S32: =S31+S27 -> 8877.6181 | T32: HPP + COVER | U32: =U31+U30 -> 9986.6417 | V32: HPP + COVER | W32: =W31+W30 -> 12260.95 | Z32: HPP + COVER | AA32: =AA31+AA30 -> 21249.261 | AB32: HPP + COVER | AC32: =AC31+AC30 -> 12750.936 | AD32: HPP + COVER | AE32: =AE31+AE30 -> 22890.532 | AF32: HPP + COVER | AG32: =AG31+AG30 -> 20616.224 | AJ32: HPP + COVER | AK32: =AK31+AK30 -> 8542.2308 | AL32: HPP + COVER | AM32: =AM31+AM30 -> 10183.503 | AN32: HPP + COVER | AO32: =AO31+AO30 -> 12042.231 | AP32: HPP + COVER | AQ32: =AQ31+AQ30 -> 13683.503 | AS32: HPP + COVER | AT32: =AT30+AT31 -> 12115.181 | AU32: HPP + COVER | AV32: =AV31+AV30 -> 14155.623 | AW32: HPP + COVER | AX32: =AX31+AX29 -> 12922.137 | AY32: HPP + COVER | AZ32: =AZ31+AZ30 -> 11704.862 | BC32: HPP + COVER | BD32: =BD31+BD30 -> 11482.144 | BE32: HPP + COVER | BF32: =BF31+BF30 -> 15192.566
A33: HPP 1 RESEP | B33: =SUM(B30:B32) -> 4919.2632 | G33: TEPUNG CAKRA ( 375 GR ) | H33: ='WEEKLY FC'!E331*0.375 -> 3511.125
A34: HPP 1 PORSI | B34: =B33/36 -> 136.6462 | D34: P.BAWAH | G34: AIR (750 ML ) | H34: =B9*0.75 -> 197.36842
D35: 1 PCS P. BAWAH | E35: ='WEEKLY FC'!E14 -> 3898.0192 | G35: KUNING TELUR (4 BUTIR) | H35: ='WEEKLY FC'!E320*4 -> 7468
A36: NESTEA | D36: MARINADE | E36: =E23 -> 198.94203 | H36: =H32+H33+H34+H35 -> 19723.493 | J36: PAKET ROMA KELAS 2,3&4 SULAWESI | V36: PAKET HOT CHESE ES THE KELAS 2,3&4 SULAWESI | AD36: PAKET AYAM UTUH KELAS 2,3&4 SULAWESI | AL36: PAKET BUCKET KELAS 2,3&4 SULAWESI | AU36: PAKET GEPREK STEE KELAS 3 & 4 SULAWESI
A37: 1 PACK / 1KG NESTEA | B37: ='WEEKLY FC'!E102 -> 54570 | D37: TEPUNG CAKRA | E37: =E24 -> 327.705 | G37: HPP 15 PORSI | H37: =SUM(H32:H35)/15 -> 1314.8996 | T37: OKE | AB37: OKE | AJ37: OKE | AT37: OKE | BM37: OKE
A38: 9LITER AIR | B38: =B9*9 -> 2368.4211 | D38: TEPUNG BRIDER | E38: =E25 -> 234.1 | G38: HPP 20 PORSI | H38: =SUM(H32:H35)/20 -> 986.17467
A39: 500 ML SIMPLE SIRUP | B39: =B18*0.5 -> 5954.386 | D39: MINYAK | E39: =E26 -> 606.10227 | G39: HPP 30 PORSI | H39: =SUM(H32:H35)/30 -> 657.44978 | J39: PAKET | L39: PAKET | N39: PAKET | P39: PAKET | R39: PAKET | V39: PAKET | X39: PAKET | Z39: PAKET | AD39: PAKET | AF39: PAKET | AH39: PAKET | AL39: PAKET | AN39: PAKET | AP39: PAKET | AR39: PAKET
